{"asctime": "2018-12-12 14:07:37,889", "threadName": "MainThread", "levelname": "INFO", "message": "_log_dir=., _log_name=pymock.log, _level=20", "lineno": 53, "filename": "log.py"}
{"asctime": "2018-12-12 14:07:38,019", "threadName": "MainThread", "levelname": "INFO", "message": "Goin' Fast @ http://0.0.0.0:8868", "lineno": 901, "filename": "app.py"}
{"asctime": "2018-12-12 14:07:38,023", "threadName": "MainThread", "levelname": "ERROR", "message": "Unable to start server", "lineno": 614, "filename": "server.py", "exc_info": "Traceback (most recent call last):\n  File \"uvloop/loop.pyx\", line 1107, in uvloop.loop.Loop._create_server\n  File \"uvloop/handles/streamserver.pyx\", line 51, in uvloop.loop.UVStreamServer.listen\n  File \"uvloop/handles/streamserver.pyx\", line 89, in uvloop.loop.UVStreamServer._fatal_error\nOSError: [Errno 48] Address already in use\n\nDuring handling of the above exception, another exception occurred:\n\nTraceback (most recent call last):\n  File \"/Users/shuyi/pyenv36/lib/python3.6/site-packages/sanic/server.py\", line 612, in serve\n    http_server = loop.run_until_complete(server_coroutine)\n  File \"uvloop/loop.pyx\", line 1446, in uvloop.loop.Loop.run_until_complete\n  File \"uvloop/loop.pyx\", line 1667, in create_server\n  File \"uvloop/loop.pyx\", line 1111, in uvloop.loop.Loop._create_server\nOSError: [Errno 48] error while attempting to bind on address ('0.0.0.0', 8868): address already in use"}
{"asctime": "2018-12-12 14:07:38,025", "threadName": "MainThread", "levelname": "INFO", "message": "Server Stopped", "lineno": 739, "filename": "app.py"}
